Have you created the S3 buckets yet? [y/n] Creating the Input and Output S3 buckets and folders within
Traceback (most recent call last):
  File "/home/ubuntu/weCloudProject/Create_AWS_Artifacts/create_s3_buckets.py", line 26, in <module>
    s3_client.create_bucket(
  File "/usr/lib/python3/dist-packages/botocore/client.py", line 553, in _api_call
    return self._make_api_call(operation_name, kwargs)
           ^^^^^^^^^^^^^^^^^^^^^^^^^^^^^^^^^^^^^^^^^^^
  File "/usr/lib/python3/dist-packages/botocore/client.py", line 946, in _make_api_call
    api_params = self._emit_api_params(
                 ^^^^^^^^^^^^^^^^^^^^^^
  File "/usr/lib/python3/dist-packages/botocore/client.py", line 1072, in _emit_api_params
    self.meta.events.emit(
  File "/usr/lib/python3/dist-packages/botocore/hooks.py", line 412, in emit
    return self._emitter.emit(aliased_event_name, **kwargs)
           ^^^^^^^^^^^^^^^^^^^^^^^^^^^^^^^^^^^^^^^^^^^^^^^^
  File "/usr/lib/python3/dist-packages/botocore/hooks.py", line 256, in emit
    return self._emit(event_name, kwargs)
           ^^^^^^^^^^^^^^^^^^^^^^^^^^^^^^
  File "/usr/lib/python3/dist-packages/botocore/hooks.py", line 239, in _emit
    response = handler(**kwargs)
               ^^^^^^^^^^^^^^^^^
  File "/usr/lib/python3/dist-packages/botocore/handlers.py", line 288, in validate_bucket_name
    raise ParamValidationError(report=error_msg)
botocore.exceptions.ParamValidationError: Parameter validation failed:
Invalid bucket name "": Bucket name must match the regex "^[a-zA-Z0-9.\-_]{1,255}$" or be an ARN matching the regex "^arn:(aws).*:(s3|s3-object-lambda):[a-z\-0-9]*:[0-9]{12}:accesspoint[/:][a-zA-Z0-9\-.]{1,63}$|^arn:(aws).*:s3-outposts:[a-z\-0-9]+:[0-9]{12}:outpost[/:][a-zA-Z0-9\-]{1,63}[/:]accesspoint[/:][a-zA-Z0-9\-]{1,63}$"
Failed to create the S3 buckets
[ERROR:] RETURN CODE:  1
[ERROR:] REFER TO THE LOG FOR THE REASON FOR THE FAILURE.
